Workbook

Sheet Tasks
A1: @dropdown
B3: For any questions or clarity needed, please don't hesitate to reach out to candie.fujisaki@okta.com with the subject line "Data Analyst Intern - [YOUR NAME]"
B4: You may (and are encouraged to) add any additional tabs or columns in this file as necessary.
B7: Sales
B8: 1. Which geo has the highest sales?
B9: 2. Which segment is better at selling CIAM?
B10: 3. Bonus - How many upsell opportunities were there in September in AMER Enterprise?
B13: People
B14: 1. Who is the top performing sales rep? What geo do they come from?
B17: Written
B18: 1. What are three questions you would ask sales leadership based on this data?

Sheet Sales Data
A1: Opportunity ID | B1: Opp Owner User ID | C1: Opp Owner Geo | D1: Segment | E1: Opportunity Type | F1: Close Date | G1: Product Line | H1: Product Family | I1: Total Price | J1: Rep Name
A2: 0061Y00000QA0nIxRU | B2: 0054z00000AAVA1E0V | C2: AMER | D2: Enterprise | E2: New Business | F2: 43714 | G2: Workforce | H2: Workforce - C | I2: 48989.32 | J2: =IFERROR(VLOOKUP(B2, People!A:B, 2, FALSE), "") -> Alice Chen
A3: 0061Y00000QA0nIxRU | B3: 0054z00000AAVA1E0V | C3: AMER | D3: Enterprise | E3: New Business | F3: 43714 | G3: Workforce | H3: Workforce - B | I3: 36741.99 | J3: =IFERROR(VLOOKUP(B3, People!A:B, 2, FALSE), "") -> Alice Chen
A4: 0061Y00000QA0nIxRU | B4: 0054z00000AAVA1E0V | C4: AMER | D4: Enterprise | E4: New Business | F4: 43714 | G4: Workforce | H4: Workforce - A | I4: 24494.66 | J4: =IFERROR(VLOOKUP(B4, People!A:B, 2, FALSE), "") -> Alice Chen
A5: 0061Y00000QA0nIxRU | B5: 0054z00000AAVA1E0V | C5: AMER | D5: Enterprise | E5: New Business | F5: 43714 | G5: Workforce | H5: Workforce - A | I5: 24494.66 | J5: =IFERROR(VLOOKUP(B5, People!A:B, 2, FALSE), "") -> Alice Chen
A6: 0061Y00000QA0nIxXH | B6: 0054z00000AAFA1E0p | C6: AMER | D6: Enterprise | E6: Upsell | F6: 43567 | G6: Workforce | H6: Workforce - B | I6: 8461.79 | J6: =IFERROR(VLOOKUP(B6, People!A:B, 2, FALSE), "") -> Bob Smith
A7: 0061Y00000QA0nIxXH | B7: 0054z00000AAFA1E0p | C7: AMER | D7: Enterprise | E7: Upsell | F7: 43567 | G7: Workforce | H7: Workforce - A | I7: 5641.19 | J7: =IFERROR(VLOOKUP(B7, People!A:B, 2, FALSE), "") -> Bob Smith
A8: 0061Y00000QA0nIxXH | B8: 0054z00000AAFA1E0p | C8: AMER | D8: Enterprise | E8: Upsell | F8: 43567 | G8: Workforce | H8: Workforce - A | I8: 2820.6 | J8: =IFERROR(VLOOKUP(B8, People!A:B, 2, FALSE), "") -> Bob Smith
A9: 0061Y00000QA0nJ1PR | B9: 0051Y00000QAVBgScR | C9: AMER | D9: Corporate | E9: New Business | F9: 43549 | G9: Workforce | H9: Workforce - C | I9: 17421.98 | J9: =IFERROR(VLOOKUP(B9, People!A:B, 2, FALSE), "") -> Charlie Day
A10: 0061Y00000QA0nJ1PR | B10: 0051Y00000QAVBgScR | C10: AMER | D10: Corporate | E10: New Business | F10: 43549 | G10: Workforce | H10: Workforce - C | I10: 52264.52 | J10: =IFERROR(VLOOKUP(B10, People!A:B, 2, FALSE), "") -> Charlie Day
A11: 0061Y00000QA0nJ1PR | B11: 0051Y00000QAVBgScR | C11: AMER | D11: Corporate | E11: New Business | F11: 43549 | G11: Workforce | H11: Workforce - B | I11: 52264.52 | J11: =IFERROR(VLOOKUP(B11, People!A:B, 2, FALSE), "") -> Charlie Day
A12: 0061Y00000QA0nJ1PR | B12: 0051Y00000QAVBgScR | C12: AMER | D12: Corporate | E12: New Business | F12: 43549 | G12: Workforce | H12: Workforce - A | I12: 17421.98 | J12: =IFERROR(VLOOKUP(B12, People!A:B, 2, FALSE), "") -> Charlie Day
A13: 0061Y00000QA0nJ1PR | B13: 0051Y00000QAVBgScR | C13: AMER | D13: Corporate | E13: New Business | F13: 43549 | G13: Workforce | H13: Workforce - A | I13: 17421.98 | J13: =IFERROR(VLOOKUP(B13, People!A:B, 2, FALSE), "") -> Charlie Day
... A436: 0061Y00000QA2upTLV | B436: 0054z00000AAFA1E0n | C436: APAC | D436: Corporate | E436: New Business | F436: 44302 | G436: Workforce | H436: Workforce - A | I436: 6645.6 | J436: =IFERROR(VLOOKUP(B436, People!A:B, 2, FALSE), "")

Sheet People
A1: Opp Owner User ID | B1: Name
A2: 0054z00000AAVA1E0V | B2: Alice Chen
A3: 0054z00000AAFA1E0p | B3: Bob Smith
A4: 0051Y00000QAVBgScR | B4: Charlie Day
A5: 0054z00000AAJA0qTj | B5: Diana Prince
A6: 0054z00000AAFA1E0i | B6: Edward Nygma
A7: 0054z00000AAVA1UwC | B7: Fiona Gallagher
A8: 0054z00000AAVA1UwD | B8: George Bluth
A9: 0054z00000AABA18jp | B9: Hannah Abbott
A10: 0054z00000AAVA1E0S | B10: Ian Wright

Sheet Q1 - Sales by Geo
A1: Q1: Which geo has the highest sales?
A2: Answer: EMEA has the highest total sales at $3,794,801.84
A4: Pivot Table:
A5: Opp Owner Geo | B5: SUM of Total Price
A6: AMER | B6: 2694035.1
A7: APAC | B7: 1121169.9
A8: EMEA | B8: 3794801.8
A9: Grand Total | B9: 7610006.8
A11: Formula-based Table:
A12: Geography | B12: Total Sales ($) | C12: Opportunities (#) | D12: Total Sales (%) | E12: Avg. Deal Size ($)
A13: EMEA | B13: =SUMIFS('Sales Data'!I$2:I1000, 'Sales Data'!C$2:C1000, A13) -> 3794801.8 | C13: =IFERROR(__xludf.DUMMYFUNCTION("COUNTUNIQUE(FILTER('Sales Data'!A$2:A1000, 'Sales Data'!C$2:C1000=A13))"),74) -> 74 | D13: =B13/SUM($B$13:$B$15) -> 0.49865945 | E13: =B13/C13 -> 51281.106
A14: AMER | B14: =SUMIFS('Sales Data'!I$2:I1000, 'Sales Data'!C$2:C1000, A14) -> 2694035.1 | C14: =IFERROR(__xludf.DUMMYFUNCTION("COUNTUNIQUE(FILTER('Sales Data'!A$2:A1000, 'Sales Data'!C$2:C1000=A14))"),44) -> 44 | D14: =B14/SUM($B$13:$B$15) -> 0.35401218 | E14: =B14/C14 -> 61228.071
A15: APAC | B15: =SUMIFS('Sales Data'!I$2:I1000, 'Sales Data'!C$2:C1000, A15) -> 1121169.9 | C15: =IFERROR(__xludf.DUMMYFUNCTION("COUNTUNIQUE(FILTER('Sales Data'!A$2:A1000, 'Sales Data'!C$2:C1000=A15))"),27) -> 27 | D15: =B15/SUM($B$13:$B$15) -> 0.14732836 | E15: =B15/C15 -> 41524.81
A16: Total | B16: =SUM(B13:B15) -> 7610006.8 | C16: =SUM(C13:C15) -> 145 | D16: =SUM(D13:D15) -> 1 | E16: =B16/C16 -> 52482.806
F19: Analysis: | G19: Actionable Insight:
F20: EMEA leads total sales at $3.79M (49.9%) across 74 opportunities, while AMER contributes $2.69M (35.4%) across 44 opportunities. AMER’s average deal size is higher at about $61.2K versus $51.3K in EMEA, which suggests EMEA is winning through volume while AMER is winning relatively larger deals. APAC is the smallest region at $1.12M (14.7%) across 27 opportunities, with the lowest average deal size at $41.5K | G20: Leadership should understand why EMEA generates more volume while AMER produces larger average deals. That could point to differences in market mix, territory coverage, or sales motion. APAC should be reviewed separately because its result is concentrated in a single deal, so this dataset does not yet provide enough evidence to judge broad pipeline health there.

Sheet Q2 - CIAM by Segment
A1: Q2: Which segment is better at selling CIAM?
A2: Answer: Enterprise generates significantly more CIAM revenue than Corporate: $1,549,139 compared to $254,328, which is about 6.1 times higher.
A4: Product Line | B4: CIAM
A6: Segment | B6: CIAM Sales ($)
A7: Corporate | B7: 254327.68
A8: Enterprise | B8: 1549139.4
A9: Grand Total | B9: 1803467.1
A11: Segment | B11: CIAM Sales ($) | C11: CIAM Opportunities ($) | D11: CIAM Line Items (#) | E11: Avg. Revenue per Opp ($)
A12: Enterprise | B12: =SUMIFS('Sales Data'!I$2:I1000, 'Sales Data'!G$2:G1000, "CIAM", 'Sales Data'!D$2:D1000, A12) -> 1549139.4 | C12: =IFERROR(__xludf.DUMMYFUNCTION("COUNTUNIQUE(FILTER('Sales Data'!A$2:A1000, 'Sales Data'!D$2:D1000=A12, 'Sales Data'!G$2:G1000=""CIAM""))"),8) -> 8 | D12: =COUNTIFS('Sales Data'!G$2:G1000, "CIAM", 'Sales Data'!D$2:D1000, A12) -> 26 | E12: =B12/C12 -> 193642.43
A13: Corporate | B13: =SUMIFS('Sales Data'!I$2:I1000, 'Sales Data'!G$2:G1000, "CIAM", 'Sales Data'!D$2:D1000, A13) -> 254327.68 | C13: =IFERROR(__xludf.DUMMYFUNCTION("COUNTUNIQUE(FILTER('Sales Data'!A$2:A1000, 'Sales Data'!D$2:D1000=A13, 'Sales Data'!G$2:G1000=""CIAM""))"),6) -> 6 | D13: =COUNTIFS('Sales Data'!G$2:G1000, "CIAM", 'Sales Data'!D$2:D1000, A13) -> 13 | E13: =B13/C13 -> 42387.947
A14: Total | B14: =SUM(B12:B13) -> 1803467.1 | C14: =SUM(C12:C13) -> 14 | D14: =SUM(D12:D13) -> 39 | E14: =B14/C14 -> 128819.08
G15: Analysis: | H15: Actionable Insights:
G16: Enterprise clearly outperforms Corporate in CIAM, generating about $1.55M versus $254K. Enterprise represents roughly 86% of total CIAM revenue and also delivers much higher average revenue per opportunity, indicating that CIAM is landing more effectively in larger accounts. | H16: CIAM is clearly landing in Enterprise, the product's value proposition likely resonates with larger, more complex identity needs. Corporate CIAM deals are small and may need a different packaging or pricing motion to scale.

Sheet Q3 - Sept AMER Ent Upsell
A1: Q3: How many upsell opportunities in September in AMER Enterprise?
A2: Answer: There are three unique upsell opportunities in September aross all years for the AMER Enterprise
A4: Opp Owner Geo | B4: AMER
A5: Segment | B5: Enterprise
A6: Opportunity Type | B6: Upsell
A7: Close Date | B7: (Multiple Items)
A9: Opportunity ID | B9: COUNTA of Opportunity ID
A10: 0061Y00000QA2orQEZ | B10: 2
A11: 0061Y00000QA2shOKZ | B11: 4
A12: 0061Y00000QA2slKVO | B12: 1
A13: Grand Total | B13: 7

Sheet Q4 - Top Performing Sales Reps
A1: Q4: Who is the top performing sales rep? What geo do they come from?
A2: Top overall performer: User ID 0051Y00000QARBgp8N from EMEA with $1,021,381.92 in sales.
A3: Top named performer: Alice Chen from AMER with $645,698.19 in sales.
A4: The People table is incomplete, the true top rep cannot be identified by name from the current mapping.
A6: ID | B6: Sum of Total Prices ($) | C6: Geography | D6: Employee Name | F6: Data Quality Note:
A7: =IFERROR(__xludf.DUMMYFUNCTION("QUERY('Sales Data'!B2:I1000, ""select B, sum(I) where B is not null group by B order by sum(I) desc label sum(I) ''"", 0)"),"0051Y00000QARBgp8N") -> 0051Y00000QARBgp8N | B7: =IFERROR(__xludf.DUMMYFUNCTION("""COMPUTED_VALUE"""),1021381.92) -> 1021381.9 | C7: =IFERROR(__xludf.DUMMYFUNCTION("INDEX(FILTER('Sales Data'!C:C, 'Sales Data'!B:B=A7), 1)"),"EMEA") -> EMEA | D7: =IFERROR(VLOOKUP(A7, People!A:B, 2, FALSE), "") | F7: 52 of 61 unique sales reps in Sales Data are not listed in the People table.
A8: =IFERROR(__xludf.DUMMYFUNCTION("""COMPUTED_VALUE"""),"0054z00000AAVA1E0V") -> 0054z00000AAVA1E0V | B8: =IFERROR(__xludf.DUMMYFUNCTION("""COMPUTED_VALUE"""),645698.19) -> 645698.19 | C8: =IFERROR(__xludf.DUMMYFUNCTION("INDEX(FILTER('Sales Data'!C:C, 'Sales Data'!B:B=A8), 1)"),"AMER") -> AMER | D8: =IFERROR(VLOOKUP(A8, People!A:B, 2, FALSE), "") -> Alice Chen | F8: The overall top representative by total sales (ID: 0051Y00000QARBgp8N, EMEA, $1,021,382) has no name mapping
A9: =IFERROR(__xludf.DUMMYFUNCTION("""COMPUTED_VALUE"""),"0054z00000AAVA1UwD") -> 0054z00000AAVA1UwD | B9: =IFERROR(__xludf.DUMMYFUNCTION("""COMPUTED_VALUE"""),512870.339999999) -> 512870.34 | C9: =IFERROR(__xludf.DUMMYFUNCTION("INDEX(FILTER('Sales Data'!C:C, 'Sales Data'!B:B=A9), 1)"),"AMER") -> AMER | D9: =IFERROR(VLOOKUP(A9, People!A:B, 2, FALSE), "") -> George Bluth
A10: =IFERROR(__xludf.DUMMYFUNCTION("""COMPUTED_VALUE"""),"0054z00000AAQ95znP") -> 0054z00000AAQ95znP | B10: =IFERROR(__xludf.DUMMYFUNCTION("""COMPUTED_VALUE"""),480718) -> 480718 | C10: =IFERROR(__xludf.DUMMYFUNCTION("INDEX(FILTER('Sales Data'!C:C, 'Sales Data'!B:B=A10), 1)"),"EMEA") -> EMEA | D10: =IFERROR(VLOOKUP(A10, People!A:B, 2, FALSE), "")
A11: =IFERROR(__xludf.DUMMYFUNCTION("""COMPUTED_VALUE"""),"0054z00000AABA18jp") -> 0054z00000AABA18jp | B11: =IFERROR(__xludf.DUMMYFUNCTION("""COMPUTED_VALUE"""),458363.53) -> 458363.53 | C11: =IFERROR(__xludf.DUMMYFUNCTION("INDEX(FILTER('Sales Data'!C:C, 'Sales Data'!B:B=A11), 1)"),"APAC") -> APAC | D11: =IFERROR(VLOOKUP(A11, People!A:B, 2, FALSE), "") -> Hannah Abbott
A12: =IFERROR(__xludf.DUMMYFUNCTION("""COMPUTED_VALUE"""),"0054z00000AAPAKOSd") -> 0054z00000AAPAKOSd | B12: =IFERROR(__xludf.DUMMYFUNCTION("""COMPUTED_VALUE"""),370834.3) -> 370834.3 | C12: =IFERROR(__xludf.DUMMYFUNCTION("INDEX(FILTER('Sales Data'!C:C, 'Sales Data'!B:B=A12), 1)"),"AMER") -> AMER | D12: =IFERROR(VLOOKUP(A12, People!A:B, 2, FALSE), "")
A13: =IFERROR(__xludf.DUMMYFUNCTION("""COMPUTED_VALUE"""),"0054z00000AAFA1E0p") -> 0054z00000AAFA1E0p | B13: =IFERROR(__xludf.DUMMYFUNCTION("""COMPUTED_VALUE"""),345898.39) -> 345898.39 | C13: =IFERROR(__xludf.DUMMYFUNCTION("INDEX(FILTER('Sales Data'!C:C, 'Sales Data'!B:B=A13), 1)"),"AMER") -> AMER | D13: =IFERROR(VLOOKUP(A13, People!A:B, 2, FALSE), "") -> Bob Smith
A14: =IFERROR(__xludf.DUMMYFUNCTION("""COMPUTED_VALUE"""),"0054z00000AAFA1E0k") -> 0054z00000AAFA1E0k | B14: =IFERROR(__xludf.DUMMYFUNCTION("""COMPUTED_VALUE"""),278603.37) -> 278603.37 | C14: =IFERROR(__xludf.DUMMYFUNCTION("INDEX(FILTER('Sales Data'!C:C, 'Sales Data'!B:B=A14), 1)"),"EMEA") -> EMEA | D14: =IFERROR(VLOOKUP(A14, People!A:B, 2, FALSE), "")
A15: =IFERROR(__xludf.DUMMYFUNCTION("""COMPUTED_VALUE"""),"0054z00000AAVA1E0S") -> 0054z00000AAVA1E0S | B15: =IFERROR(__xludf.DUMMYFUNCTION("""COMPUTED_VALUE"""),260459.87) -> 260459.87 | C15: =IFERROR(__xludf.DUMMYFUNCTION("INDEX(FILTER('Sales Data'!C:C, 'Sales Data'!B:B=A15), 1)"),"AMER") -> AMER | D15: =IFERROR(VLOOKUP(A15, People!A:B, 2, FALSE), "") -> Ian Wright
A16: =IFERROR(__xludf.DUMMYFUNCTION("""COMPUTED_VALUE"""),"0054z00000AAE97J5t") -> 0054z00000AAE97J5t | B16: =IFERROR(__xludf.DUMMYFUNCTION("""COMPUTED_VALUE"""),232200.979999999) -> 232200.98 | C16: =IFERROR(__xludf.DUMMYFUNCTION("INDEX(FILTER('Sales Data'!C:C, 'Sales Data'!B:B=A16), 1)"),"APAC") -> APAC | D16: =IFERROR(VLOOKUP(A16, People!A:B, 2, FALSE), "")
A17: =IFERROR(__xludf.DUMMYFUNCTION("""COMPUTED_VALUE"""),"0054z00000AAVA1UwE") -> 0054z00000AAVA1UwE | B17: =IFERROR(__xludf.DUMMYFUNCTION("""COMPUTED_VALUE"""),217866.38) -> 217866.38 | C17: =IFERROR(__xludf.DUMMYFUNCTION("INDEX(FILTER('Sales Data'!C:C, 'Sales Data'!B:B=A17), 1)"),"EMEA") -> EMEA | D17: =IFERROR(VLOOKUP(A17, People!A:B, 2, FALSE), "")
A18: =IFERROR(__xludf.DUMMYFUNCTION("""COMPUTED_VALUE"""),"0054z00000AADAKaw6") -> 0054z00000AADAKaw6 | B18: =IFERROR(__xludf.DUMMYFUNCTION("""COMPUTED_VALUE"""),210070.83) -> 210070.83 | C18: =IFERROR(__xludf.DUMMYFUNCTION("INDEX(FILTER('Sales Data'!C:C, 'Sales Data'!B:B=A18), 1)"),"APAC") -> APAC | D18: =IFERROR(VLOOKUP(A18, People!A:B, 2, FALSE), "")
A19: =IFERROR(__xludf.DUMMYFUNCTION("""COMPUTED_VALUE"""),"0054z00000AAFA1E0j") -> 0054z00000AAFA1E0j | B19: =IFERROR(__xludf.DUMMYFUNCTION("""COMPUTED_VALUE"""),164947.2) -> 164947.2 | C19: =IFERROR(__xludf.DUMMYFUNCTION("INDEX(FILTER('Sales Data'!C:C, 'Sales Data'!B:B=A19), 1)"),"EMEA") -> EMEA | D19: =IFERROR(VLOOKUP(A19, People!A:B, 2, FALSE), "")
A20: =IFERROR(__xludf.DUMMYFUNCTION("""COMPUTED_VALUE"""),"0054z00000AAFA1Iw8") -> 0054z00000AAFA1Iw8 | B20: =IFERROR(__xludf.DUMMYFUNCTION("""COMPUTED_VALUE"""),161652.38) -> 161652.38 | C20: =IFERROR(__xludf.DUMMYFUNCTION("INDEX(FILTER('Sales Data'!C:C, 'Sales Data'!B:B=A20), 1)"),"EMEA") -> EMEA | D20: =IFERROR(VLOOKUP(A20, People!A:B, 2, FALSE), "")
A21: =IFERROR(__xludf.DUMMYFUNCTION("""COMPUTED_VALUE"""),"0051Y00000QAVBgScR") -> 0051Y00000QAVBgScR | B21: =IFERROR(__xludf.DUMMYFUNCTION("""COMPUTED_VALUE"""),161574.7) -> 161574.7 | C21: =IFERROR(__xludf.DUMMYFUNCTION("INDEX(FILTER('Sales Data'!C:C, 'Sales Data'!B:B=A21), 1)"),"AMER") -> AMER | D21: =IFERROR(VLOOKUP(A21, People!A:B, 2, FALSE), "") -> Charlie Day
A22: =IFERROR(__xludf.DUMMYFUNCTION("""COMPUTED_VALUE"""),"0054z00000AAU9yY6Y") -> 0054z00000AAU9yY6Y | B22: =IFERROR(__xludf.DUMMYFUNCTION("""COMPUTED_VALUE"""),157245.129999999) -> 157245.13 | C22: =IFERROR(__xludf.DUMMYFUNCTION("INDEX(FILTER('Sales Data'!C:C, 'Sales Data'!B:B=A22), 1)"),"EMEA") -> EMEA | D22: =IFERROR(VLOOKUP(A22, People!A:B, 2, FALSE), "")
A23: =IFERROR(__xludf.DUMMYFUNCTION("""COMPUTED_VALUE"""),"0051Y00000QARBei3T") -> 0051Y00000QARBei3T | B23: =IFERROR(__xludf.DUMMYFUNCTION("""COMPUTED_VALUE"""),156752.669999999) -> 156752.67 | C23: =IFERROR(__xludf.DUMMYFUNCTION("INDEX(FILTER('Sales Data'!C:C, 'Sales Data'!B:B=A23), 1)"),"EMEA") -> EMEA | D23: =IFERROR(VLOOKUP(A23, People!A:B, 2, FALSE), "")
A24: =IFERROR(__xludf.DUMMYFUNCTION("""COMPUTED_VALUE"""),"0054z00000AAY98dRX") -> 0054z00000AAY98dRX | B24: =IFERROR(__xludf.DUMMYFUNCTION("""COMPUTED_VALUE"""),149466.939999999) -> 149466.94 | C24: =IFERROR(__xludf.DUMMYFUNCTION("INDEX(FILTER('Sales Data'!C:C, 'Sales Data'!B:B=A24), 1)"),"EMEA") -> EMEA | D24: =IFERROR(VLOOKUP(A24, People!A:B, 2, FALSE), "")
A25: =IFERROR(__xludf.DUMMYFUNCTION("""COMPUTED_VALUE"""),"0054z00000AAFA1E0o") -> 0054z00000AAFA1E0o | B25: =IFERROR(__xludf.DUMMYFUNCTION("""COMPUTED_VALUE"""),143553.54) -> 143553.54 | C25: =IFERROR(__xludf.DUMMYFUNCTION("INDEX(FILTER('Sales Data'!C:C, 'Sales Data'!B:B=A25), 1)"),"AMER") -> AMER | D25: =IFERROR(VLOOKUP(A25, People!A:B, 2, FALSE), "")
A26: =IFERROR(__xludf.DUMMYFUNCTION("""COMPUTED_VALUE"""),"0054z00000AAVA1E1V") -> 0054z00000AAVA1E1V | B26: =IFERROR(__xludf.DUMMYFUNCTION("""COMPUTED_VALUE"""),119346.74) -> 119346.74 | C26: =IFERROR(__xludf.DUMMYFUNCTION("INDEX(FILTER('Sales Data'!C:C, 'Sales Data'!B:B=A26), 1)"),"EMEA") -> EMEA | D26: =IFERROR(VLOOKUP(A26, People!A:B, 2, FALSE), "")
A27: =IFERROR(__xludf.DUMMYFUNCTION("""COMPUTED_VALUE"""),"0054z00000AAA998l9") -> 0054z00000AAA998l9 | B27: =IFERROR(__xludf.DUMMYFUNCTION("""COMPUTED_VALUE"""),106366.2) -> 106366.2 | C27: =IFERROR(__xludf.DUMMYFUNCTION("INDEX(FILTER('Sales Data'!C:C, 'Sales Data'!B:B=A27), 1)"),"EMEA") -> EMEA | D27: =IFERROR(VLOOKUP(A27, People!A:B, 2, FALSE), "")
A28: =IFERROR(__xludf.DUMMYFUNCTION("""COMPUTED_VALUE"""),"0054z00000AAVA1E0X") -> 0054z00000AAVA1E0X | B28: =IFERROR(__xludf.DUMMYFUNCTION("""COMPUTED_VALUE"""),81557.99) -> 81557.99 | C28: =IFERROR(__xludf.DUMMYFUNCTION("INDEX(FILTER('Sales Data'!C:C, 'Sales Data'!B:B=A28), 1)"),"AMER") -> AMER | D28: =IFERROR(VLOOKUP(A28, People!A:B, 2, FALSE), "")
A29: =IFERROR(__xludf.DUMMYFUNCTION("""COMPUTED_VALUE"""),"0054z00000AAFA1E0g") -> 0054z00000AAFA1E0g | B29: =IFERROR(__xludf.DUMMYFUNCTION("""COMPUTED_VALUE"""),66665.59) -> 66665.59 | C29: =IFERROR(__xludf.DUMMYFUNCTION("INDEX(FILTER('Sales Data'!C:C, 'Sales Data'!B:B=A29), 1)"),"EMEA") -> EMEA | D29: =IFERROR(VLOOKUP(A29, People!A:B, 2, FALSE), "")
A30: =IFERROR(__xludf.DUMMYFUNCTION("""COMPUTED_VALUE"""),"0054z00000AAFA1E0i") -> 0054z00000AAFA1E0i | B30: =IFERROR(__xludf.DUMMYFUNCTION("""COMPUTED_VALUE"""),65943.1) -> 65943.1 | C30: =IFERROR(__xludf.DUMMYFUNCTION("INDEX(FILTER('Sales Data'!C:C, 'Sales Data'!B:B=A30), 1)"),"EMEA") -> EMEA | D30: =IFERROR(VLOOKUP(A30, People!A:B, 2, FALSE), "") -> Edward Nygma
A31: =IFERROR(__xludf.DUMMYFUNCTION("""COMPUTED_VALUE"""),"0054z00000AAFA1E0n") -> 0054z00000AAFA1E0n | B31: =IFERROR(__xludf.DUMMYFUNCTION("""COMPUTED_VALUE"""),64752) -> 64752 | C31: =IFERROR(__xludf.DUMMYFUNCTION("INDEX(FILTER('Sales Data'!C:C, 'Sales Data'!B:B=A31), 1)"),"APAC") -> APAC | D31: =IFERROR(VLOOKUP(A31, People!A:B, 2, FALSE), "")
A32: =IFERROR(__xludf.DUMMYFUNCTION("""COMPUTED_VALUE"""),"0054z00000AAVA1E1Q") -> 0054z00000AAVA1E1Q | B32: =IFERROR(__xludf.DUMMYFUNCTION("""COMPUTED_VALUE"""),59709.87) -> 59709.87 | C32: =IFERROR(__xludf.DUMMYFUNCTION("INDEX(FILTER('Sales Data'!C:C, 'Sales Data'!B:B=A32), 1)"),"EMEA") -> EMEA | D32: =IFERROR(VLOOKUP(A32, People!A:B, 2, FALSE), "")
A33: =IFERROR(__xludf.DUMMYFUNCTION("""COMPUTED_VALUE"""),"0054z00000AAFA1E1h") -> 0054z00000AAFA1E1h | B33: =IFERROR(__xludf.DUMMYFUNCTION("""COMPUTED_VALUE"""),57370.2799999999) -> 57370.28 | C33: =IFERROR(__xludf.DUMMYFUNCTION("INDEX(FILTER('Sales Data'!C:C, 'Sales Data'!B:B=A33), 1)"),"EMEA") -> EMEA | D33: =IFERROR(VLOOKUP(A33, People!A:B, 2, FALSE), "")
A34: =IFERROR(__xludf.DUMMYFUNCTION("""COMPUTED_VALUE"""),"0051Y00000QANBgSQz") -> 0051Y00000QANBgSQz | B34: =IFERROR(__xludf.DUMMYFUNCTION("""COMPUTED_VALUE"""),54493.92) -> 54493.92 | C34: =IFERROR(__xludf.DUMMYFUNCTION("INDEX(FILTER('Sales Data'!C:C, 'Sales Data'!B:B=A34), 1)"),"EMEA") -> EMEA | D34: =IFERROR(VLOOKUP(A34, People!A:B, 2, FALSE), "")
A35: =IFERROR(__xludf.DUMMYFUNCTION("""COMPUTED_VALUE"""),"0054z00000AA29aDWI") -> 0054z00000AA29aDWI | B35: =IFERROR(__xludf.DUMMYFUNCTION("""COMPUTED_VALUE"""),53900.92) -> 53900.92 | C35: =IFERROR(__xludf.DUMMYFUNCTION("INDEX(FILTER('Sales Data'!C:C, 'Sales Data'!B:B=A35), 1)"),"EMEA") -> EMEA | D35: =IFERROR(VLOOKUP(A35, People!A:B, 2, FALSE), "")
A36: =IFERROR(__xludf.DUMMYFUNCTION("""COMPUTED_VALUE"""),"0054z00000AAS9Iy8C") -> 0054z00000AAS9Iy8C | B36: =IFERROR(__xludf.DUMMYFUNCTION("""COMPUTED_VALUE"""),49979.0099999999) -> 49979.01 | C36: =IFERROR(__xludf.DUMMYFUNCTION("INDEX(FILTER('Sales Data'!C:C, 'Sales Data'!B:B=A36), 1)"),"AMER") -> AMER | D36: =IFERROR(VLOOKUP(A36, People!A:B, 2, FALSE), "")
A37: =IFERROR(__xludf.DUMMYFUNCTION("""COMPUTED_VALUE"""),"0054z00000AAPAKIS3") -> 0054z00000AAPAKIS3 | B37: =IFERROR(__xludf.DUMMYFUNCTION("""COMPUTED_VALUE"""),49364.57) -> 49364.57 | C37: =IFERROR(__xludf.DUMMYFUNCTION("INDEX(FILTER('Sales Data'!C:C, 'Sales Data'!B:B=A37), 1)"),"EMEA") -> EMEA | D37: =IFERROR(VLOOKUP(A37, People!A:B, 2, FALSE), "")
A38: =IFERROR(__xludf.DUMMYFUNCTION("""COMPUTED_VALUE"""),"0051Y00000QARBgp8W") -> 0051Y00000QARBgp8W | B38: =IFERROR(__xludf.DUMMYFUNCTION("""COMPUTED_VALUE"""),44697.63) -> 44697.63 | C38: =IFERROR(__xludf.DUMMYFUNCTION("INDEX(FILTER('Sales Data'!C:C, 'Sales Data'!B:B=A38), 1)"),"AMER") -> AMER | D38: =IFERROR(VLOOKUP(A38, People!A:B, 2, FALSE), "")
A39: =IFERROR(__xludf.DUMMYFUNCTION("""COMPUTED_VALUE"""),"0054z00000AAQ98tcW") -> 0054z00000AAQ98tcW | B39: =IFERROR(__xludf.DUMMYFUNCTION("""COMPUTED_VALUE"""),44562.44) -> 44562.44 | C39: =IFERROR(__xludf.DUMMYFUNCTION("INDEX(FILTER('Sales Data'!C:C, 'Sales Data'!B:B=A39), 1)"),"AMER") -> AMER | D39: =IFERROR(VLOOKUP(A39, People!A:B, 2, FALSE), "")
A40: =IFERROR(__xludf.DUMMYFUNCTION("""COMPUTED_VALUE"""),"0054z00000AAFA1E1c") -> 0054z00000AAFA1E1c | B40: =IFERROR(__xludf.DUMMYFUNCTION("""COMPUTED_VALUE"""),38721.69) -> 38721.69 | C40: =IFERROR(__xludf.DUMMYFUNCTION("INDEX(FILTER('Sales Data'!C:C, 'Sales Data'!B:B=A40), 1)"),"EMEA") -> EMEA | D40: =IFERROR(VLOOKUP(A40, People!A:B, 2, FALSE), "")
A41: =IFERROR(__xludf.DUMMYFUNCTION("""COMPUTED_VALUE"""),"0054z00000AAVA1E1X") -> 0054z00000AAVA1E1X | B41: =IFERROR(__xludf.DUMMYFUNCTION("""COMPUTED_VALUE"""),38449.19) -> 38449.19 | C41: =IFERROR(__xludf.DUMMYFUNCTION("INDEX(FILTER('Sales Data'!C:C, 'Sales Data'!B:B=A41), 1)"),"EMEA") -> EMEA | D41: =IFERROR(VLOOKUP(A41, People!A:B, 2, FALSE), "")
...

Sheet Q5 - Executive 
A1: Q5: Three Questions for sales leadership based on this data
A3: 1. Why is the People table incomplete? How does this affect pipeline visibility?
A4: 52 of 61 unique reps in the Sales Data do not have a matching name in the People table. Those unmapped reps account for about $5.13M of $7.61M total sales (67.4%). That creates a major visibility gap because leadership cannot reliably attribute most revenue to named individuals, which weakens coaching, performance management, and territory planning.
A6: 2. What is driving EMEA's outsized sales performance? Is the sales pipeline in AMER healthy?
A7: EMEA leads with $3.79M (49.9%), while AMER contributes $2.69M (35.4%). However, AMER’s average deal size is higher, while EMEA closes more opportunities. This raises an important leadership question: is EMEA outperforming because of stronger coverage and volume, or is AMER under-converting despite larger deal potential? The dataset supports a question about sales motion differences, but not a conclusion about broader market potential on its own.
A9: 3. How should we expand CIAM adoption in the Corporate segment?
A10: CIAM revenue is concentrated in Enterprise, which contributes about $1.55M compared with $254K in Corporate. Corporate has only 6 CIAM opportunities in the dataset, which suggests weaker penetration. APAC contributes about $194K in CIAM across 2 opportunities, so the issue is less about complete absence and more about limited scale. Leadership should ask whether packaging, enablement, or cross-sell strategy is preventing broader Corporate and regional CIAM adoption.
